Workbook

Sheet 01
A1: Ngày 01/08/2026 VINFAST TÂN HƯNG THU BÁN XE
A2: THU BÁN XE
A3: STT | B3: HỌ VÀ TÊN | C3: LOẠI XE | D3: POS | E3: GÓP | F3: TIỀN MẶT | G3: CHUYỂN KHOẢN | H3: CKCN | I3: NV BÁN | J3: GHI CHÚ
A4: 1 | B4: TRỊNH THỊ KIM CÚC | C4: vero x | G4: 32900000
A5: 2 | B5: TRẦN CAO TRÍ | C5: EVO GRAND LITE | F5: 16500000
A6: 3 | B6: NGUYỄN THỊ BÊ LÊ | C6: EVO GRAND | E6: 10000000 | G6: 11050000 | H6: 1000000
F7: =SUM(F4:F6) -> 16500000 | G7: =SUM(G4:G6) -> 43950000 | H7: =SUM(H4:H6) -> 1000000 | I7: =F7+G7 -> 60450000
A8: THU BIỂN SỐ
A9: STT | B9: HỌ VÀ TÊN | C9: LOẠI XE | D9: CHUYỂN KHOẢN | E9: TIỀN MẶT | F9: NGƯỜI GIAO BIỂN SỐ | G9: NGƯỜI GIỮ BSỐ | I9: GHI CHÚ
A10: 1 | B10: NGUYỄN VĂN THIỆN | E10: 1623000
D12: =SUM(D10:D11) -> 0 | E12: =SUM(E10:E11) -> 1623000 | W12: =6+3+6+2+3+5+16+14+4 -> 59
A13: CHI THUẾ + ĐĂNG KÝ BIỂN SỐ
A14: STT | B14: HỌ VÀ TÊN | C14: LOẠI XE | D14: THUẾ | E14: PHÍ BIỂN SỐ | F14: PHÍ CÔNG AN | G14: NGƯỜI NHÂN | I14: GHI CHÚ
A15: 1 | B15: NGUYỄN THỊ BÊ LÊ | C15: EVO GRAND | D15: 480000 | E15: 105000 | F15: 100000
A16: 2 | B16: NGUYỄN VĂN THIỆN | C16: Feliz 2025 | D16: 518000 | E16: 105000
A17: 3
A18: 4
D20: =SUM(D15:D19) -> 998000 | E20: =SUM(E15:E19) -> 210000 | F20: =SUM(F15:F19) -> 100000 | G20: =D20+E20+F20 -> 1308000
A21: THU KHOẢN KHÁC
A22: STT | B22: NỘI DUNG | E22: SỐ TIỀN | F22: NGƯỜI THU | G22: CHT/KTT | I22: GHI CHÚ
B23: Thu quỹ giữ tiền mặt tại cửa hàng ngày 31/07/2026 | E23: 2000000
E26: =SUM(E23:E25) -> 2000000
A27: CHI PHÍ
A28: STT | B28: NỘI DUNG | E28: SỐ TIỀN CHI | F28: CKCN | G28: NGƯỜI CHI TIỀN | I28: NGƯỜI NHÂN TIỀN
B29: Chi quỹ giữ tiền mặt tại cửa hàng ngày 01/08/2026 | E29: 2000000
E32: =SUM(E29:E31) -> 2000000 | F32: =SUM(F29:F30) -> 0
C33: TM | D33: CK | G33: TIỀN MẶT | H33: CKCN | I33: CHUYỂN KHOẢN
A34: Bán Xe | C34: =F7 -> 16500000 | E34: DV NỘP VỀ | G34: =C36 -> 70000
A35: Biển Số | C35: =E12 -> 1623000 | E35: BH NỘP VỀ | G35: =C39-C36 -> 16815000 | H35: =H7 -> 1000000 | I35: =G7 -> 43950000 | J35: =I35+H35 -> 44950000
A36: Dịch Vụ | C36: 70000
A37: Thu khác | C37: =E26 -> 2000000 | E37: CỬA HÀNG TRƯỞNG
A38: Chi Phí | C38: =E32+G20 -> 3308000 | D38: =F32 -> 0
A39: TỔNG NỘP VỀ | C39: =C34+C35+C36+C37-C38 -> 16885000 | E39: Huỳnh Trọng Nhân

Sheet 02
A1: Ngày 02/08/2026 VINFAST TÂN HƯNG THU BÁN XE
A2: THU BÁN XE
A3: STT | B3: HỌ VÀ TÊN | C3: LOẠI XE | D3: POS | E3: GÓP | F3: TIỀN MẶT | G3: CHUYỂN KHOẢN | H3: CKCN | I3: NV BÁN | J3: GHI CHÚ
A4: 1 | B4: NGUYỄN THÙY DƯƠNG | C4: EVO GRAND LITE | F4: 15300000
A5: 2 | B5: LÊ QUANG THIÊN | C5: EVO GRAND LITE | G5: 16500000 | H5: 800000
A6: 3 | B6: NGUYỄN NGỌC VÂN THÙY | C6: FELIZ 2025 | G6: 25480000
F7: =SUM(F4:F6) -> 15300000 | G7: =SUM(G4:G6) -> 41980000 | H7: =SUM(H4:H6) -> 800000 | I7: =F7+G7 -> 57280000
A8: THU BIỂN SỐ
A9: STT | B9: HỌ VÀ TÊN | C9: LOẠI XE | D9: CHUYỂN KHOẢN | E9: TIỀN MẶT | F9: NGƯỜI GIAO BIỂN SỐ | G9: NGƯỜI GIỮ BSỐ | I9: GHI CHÚ
A10: 1 | B10: TÔ QUỐC NGUYÊN | C10: Evo Grand Lite | D10: 1000000
D12: =SUM(D10:D11) -> 1000000 | E12: =SUM(E10:E11) -> 0 | W12: =6+3+6+2+3+5+16+14+4 -> 59
A13: CHI THUẾ + ĐĂNG KÝ BIỂN SỐ
A14: STT | B14: HỌ VÀ TÊN | C14: LOẠI XE | D14: THUẾ | E14: PHÍ BIỂN SỐ | F14: PHÍ CÔNG AN | G14: NGƯỜI NHÂN | I14: GHI CHÚ
A15: 1 | B15: LÊ QUANG THIÊN | C15: EVO GRAND LITE | D15: 378000 | E15: 105000 | F15: 100000
A16: 2 | B16: NGUYỄN THÙY DƯƠNG | C16: EVO GRAND LITE | D16: 378000 | E16: 105000 | F16: 100000
A17: 3
A18: 4
D20: =SUM(D15:D19) -> 756000 | E20: =SUM(E15:E19) -> 210000 | F20: =SUM(F15:F19) -> 200000 | G20: =D20+E20+F20 -> 1166000
A21: THU KHOẢN KHÁC
A22: STT | B22: NỘI DUNG | E22: SỐ TIỀN | F22: NGƯỜI THU | G22: CHT/KTT | I22: GHI CHÚ
B23: Thu quỹ giữ tiền mặt tại cửa hàng ngày 01/08/2026 | E23: 2000000
E26: =SUM(E23:E25) -> 2000000
A27: CHI PHÍ
A28: STT | B28: NỘI DUNG | E28: SỐ TIỀN CHI | F28: CKCN | G28: NGƯỜI CHI TIỀN | I28: NGƯỜI NHÂN TIỀN
B29: Chi quỹ giữ tiền mặt tại cửa hàng ngày 02/08/2026 | E29: 2000000
E32: =SUM(E29:E31) -> 2000000 | F32: =SUM(F29:F30) -> 0
C33: TM | D33: CK | G33: TIỀN MẶT | H33: CKCN | I33: CHUYỂN KHOẢN
A34: Bán Xe | C34: =F7 -> 15300000 | E34: DV NỘP VỀ | G34: =C36 -> 230000
A35: Biển Số | C35: =E12 -> 0 | E35: BH NỘP VỀ | G35: =C39-C36 -> 14134000 | H35: =H7+D12 -> 1800000 | I35: =G7 -> 41980000 | J35: =I35+H35 -> 43780000
A36: Dịch Vụ | C36: =90000+140000 -> 230000
A37: Thu khác | C37: =E26 -> 2000000 | E37: CỬA HÀNG TRƯỞNG
A38: Chi Phí | C38: =E32+G20 -> 3166000 | D38: =F32 -> 0
A39: TỔNG NỘP VỀ | C39: =C34+C35+C36+C37-C38 -> 14364000 | E39: Huỳnh Trọng Nhân

Sheet 03
A1: Ngày 03/08/2026 VINFAST TÂN HƯNG THU BÁN XE
A2: THU BÁN XE
A3: STT | B3: HỌ VÀ TÊN | C3: LOẠI XE | D3: POS | E3: GÓP | F3: TIỀN MẶT | G3: CHUYỂN KHOẢN | H3: CKCN | I3: NV BÁN | J3: GHI CHÚ
A4: 1 | B4: NGUYỄN THỊ HẢO | C4: EVO GRAND LITE | G4: 16500000 | H4: 800000
A5: 2
A6: 3
F7: =SUM(F4:F6) -> 0 | G7: =SUM(G4:G6) -> 16500000 | H7: =SUM(H4:H6) -> 800000 | I7: =F7+G7 -> 16500000
A8: THU BIỂN SỐ
A9: STT | B9: HỌ VÀ TÊN | C9: LOẠI XE | D9: CHUYỂN KHOẢN | E9: TIỀN MẶT | F9: NGƯỜI GIAO BIỂN SỐ | G9: NGƯỜI GIỮ BSỐ | I9: GHI CHÚ
A10: 1
E12: =SUM(E10:E11) -> 0 | W12: =6+3+6+2+3+5+16+14+4 -> 59
A13: CHI THUẾ + ĐĂNG KÝ BIỂN SỐ
A14: STT | B14: HỌ VÀ TÊN | C14: LOẠI XE | D14: THUẾ | E14: PHÍ BIỂN SỐ | F14: PHÍ CÔNG AN | G14: NGƯỜI NHÂN | I14: GHI CHÚ
A15: 1
A16: 2
A17: 3
A18: 4
D20: =SUM(D15:D19) -> 0 | E20: =SUM(E15:E19) -> 0 | F20: =SUM(F15:F19) -> 0 | G20: =D20+E20+F20 -> 0
A21: THU KHOẢN KHÁC
A22: STT | B22: NỘI DUNG | E22: SỐ TIỀN | F22: NGƯỜI THU | G22: CHT/KTT | I22: GHI CHÚ
B23: Thu quỹ giữ tiền mặt tại cửa hàng ngày 02/08/2026 | E23: 2000000
E26: =SUM(E23:E25) -> 2000000
A27: CHI PHÍ
A28: STT | B28: NỘI DUNG | E28: SỐ TIỀN CHI | F28: CKCN | G28: NGƯỜI CHI TIỀN | I28: NGƯỜI NHÂN TIỀN
B29: Chi quỹ giữ tiền mặt tại cửa hàng ngày 03/08/2026 | E29: 2000000
E32: =SUM(E29:E31) -> 2000000 | F32: =SUM(F29:F30) -> 0
C33: TM | D33: CK | G33: TIỀN MẶT | H33: CKCN | I33: CHUYỂN KHOẢN
A34: Bán Xe | C34: =F7 -> 0 | E34: DV NỘP VỀ | G34: =C36
A35: Biển Số | C35: =E12 -> 0 | E35: BH NỘP VỀ | G35: =C39-C36 -> 0 | H35: =H7+D12 -> 800000 | I35: =G7 -> 16500000 | J35: =I35+H35 -> 17300000
A36: Dịch Vụ
A37: Thu khác | C37: =E26 -> 2000000 | E37: CỬA HÀNG TRƯỞNG
A38: Chi Phí | C38: =E32+G20 -> 2000000 | D38: =F32 -> 0
A39: TỔNG NỘP VỀ | C39: =C34+C35+C36+C37-C38 -> 0 | E39: Huỳnh Trọng Nhân

Sheet 04
A1: Ngày 04/08/2026 VINFAST TÂN HƯNG THU BÁN XE
A2: THU BÁN XE
A3: STT | B3: HỌ VÀ TÊN | C3: LOẠI XE | D3: POS | E3: GÓP | F3: TIỀN MẶT | G3: CHUYỂN KHOẢN | H3: CKCN | I3: NV BÁN | J3: GHI CHÚ
A4: 1 | B4: LÊ THỊ LỘC | C4: EVO LITE | E4: 18900000 | F4: 870000
A5: 2
A6: 3
F7: =SUM(F4:F6) -> 870000 | G7: =SUM(G4:G6) -> 0 | H7: =SUM(H4:H6) -> 0 | I7: =F7+G7 -> 870000
A8: THU BIỂN SỐ
A9: STT | B9: HỌ VÀ TÊN | C9: LOẠI XE | D9: CHUYỂN KHOẢN | E9: TIỀN MẶT | F9: NGƯỜI GIAO BIỂN SỐ | G9: NGƯỜI GIỮ BSỐ | I9: GHI CHÚ
A10: 1
E12: =SUM(E10:E11) -> 0 | W12: =6+3+6+2+3+5+16+14+4 -> 59
A13: CHI THUẾ + ĐĂNG KÝ BIỂN SỐ
A14: STT | B14: HỌ VÀ TÊN | C14: LOẠI XE | D14: THUẾ | E14: PHÍ BIỂN SỐ | F14: PHÍ CÔNG AN | G14: NGƯỜI NHÂN | I14: GHI CHÚ
A15: 1 | B15: LÊ THỊ LỘC | C15: EVO LITE | D15: 340000 | E15: 105000 | F15: 100000
A16: 2
A17: 3
A18: 4
D20: =SUM(D15:D19) -> 340000 | E20: =SUM(E15:E19) -> 105000 | F20: =SUM(F15:F19) -> 100000 | G20: =D20+E20+F20 -> 545000
A21: THU KHOẢN KHÁC
A22: STT | B22: NỘI DUNG | E22: SỐ TIỀN | F22: NGƯỜI THU | G22: CHT/KTT | I22: GHI CHÚ
B23: Thu quỹ giữ tiền mặt tại cửa hàng ngày 03/08/2026 | E23: 2000000
E26: =SUM(E23:E25) -> 2000000
A27: CHI PHÍ
A28: STT | B28: NỘI DUNG | E28: SỐ TIỀN CHI | F28: CKCN | G28: NGƯỜI CHI TIỀN | I28: NGƯỜI NHÂN TIỀN
B29: Chi quỹ giữ tiền mặt tại cửa hàng ngày 04/08/2026 | E29: 264000
B30: ĐÓNG TIỀN NƯỚC THÁNG 7 | E30: 61000
B31: Hoàn tiền cho khách Lưu Hoàng Đoan Thư | E31: 2000000
E32: =SUM(E29:E31) -> 2325000 | F32: =SUM(F29:F30) -> 0
C33: TM | D33: CK | G33: TIỀN MẶT | H33: CKCN | I33: CHUYỂN KHOẢN
A34: Bán Xe | C34: =F7 -> 870000 | E34: DV NỘP VỀ | G34: =C36
A35: Biển Số | C35: =E12 -> 0 | E35: BH NỘP VỀ | G35: =C39-C36 -> 0 | H35: =H7+D12 -> 0 | I35: =G7 -> 0 | J35: =I35+H35 -> 0
A36: Dịch Vụ
A37: Thu khác | C37: =E26 -> 2000000 | E37: CỬA HÀNG TRƯỞNG
A38: Chi Phí | C38: =E32+G20 -> 2870000 | D38: =F32 -> 0
A39: TỔNG NỘP VỀ | C39: =C34+C35+C36+C37-C38 -> 0 | E39: Huỳnh Trọng Nhân
L42: =G20+'06'!G20+'06'!E30+'06'!E31+'06'!E32+'06'!E33+'06'!E34 -> 1891000 | M42: =L42-G20 -> 1346000

Sheet 05
A1: Ngày 05/08/2026 VINFAST TÂN HƯNG THU BÁN XE
A3: STT | B3: HỌ VÀ TÊN | C3: LOẠI XE | D3: POS | E3: GÓP | F3: TIỀN MẶT | G3: CHUYỂN KHOẢN | H3: CKCN | I3: NV BÁN | J3: GHI CHÚ
A4: 1
A5: 2
A6: 3
F7: =SUM(F4:F6) -> 0 | G7: =SUM(G4:G6) -> 0 | H7: =SUM(H4:H6) -> 0 | I7: =F7+G7 -> 0
A8: THU BIỂN SỐ
A9: STT | B9: HỌ VÀ TÊN | C9: LOẠI XE | D9: CHUYỂN KHOẢN | E9: TIỀN MẶT | F9: NGƯỜI GIAO BIỂN SỐ | G9: NGƯỜI GIỮ BSỐ | I9: GHI CHÚ
A10: 1
E12: =SUM(E10:E11) -> 0 | W12: =6+3+6+2+3+5+16+14+4 -> 59
A13: CHI THUẾ + ĐĂNG KÝ BIỂN SỐ
A14: STT | B14: HỌ VÀ TÊN | C14: LOẠI XE | D14: THUẾ | E14: PHÍ BIỂN SỐ | F14: PHÍ CÔNG AN | G14: NGƯỜI NHÂN | I14: GHI CHÚ
A15: 1
A16: 2
A17: 3
A18: 4
D20: =SUM(D15:D19) -> 0 | E20: =SUM(E15:E19) -> 0 | F20: =SUM(F15:F19) -> 0 | G20: =D20+E20+F20 -> 0
A21: THU KHOẢN KHÁC
A22: STT | B22: NỘI DUNG | E22: SỐ TIỀN | F22: NGƯỜI THU | G22: CHT/KTT | I22: GHI CHÚ
B23: Thu quỹ giữ tiền mặt tại cửa hàng ngày 04/08/2026 | E23: 264000
E26: =SUM(E23:E25) -> 264000
A27: CHI PHÍ
A28: STT | B28: NỘI DUNG | E28: SỐ TIỀN CHI | F28: CKCN | G28: NGƯỜI CHI TIỀN | I28: NGƯỜI NHÂN TIỀN
B29: Chi quỹ giữ tiền mặt tại cửa hàng ngày 05/08/2026 | E29: 264000
E34: =SUM(E29:E33) -> 264000 | F34: =SUM(F29:F30) -> 0
C35: TM | D35: CK | G35: TIỀN MẶT | H35: CKCN | I35: CHUYỂN KHOẢN
A36: Bán Xe | C36: =F7 -> 0 | E36: DV NỘP VỀ | G36: =C38 -> 190000
A37: Biển Số | C37: =E12 -> 0 | E37: BH NỘP VỀ | G37: =C41-C38 -> 0 | H37: =H7+D12 -> 0 | I37: =G7 -> 0 | J37: =I37+H37 -> 0
A38: Dịch Vụ | C38: =60000+70000+60000 -> 190000
A39: Thu khác | C39: =E26 -> 264000 | E39: CỬA HÀNG TRƯỞNG
A40: Chi Phí | C40: =E34+G20 -> 264000 | D40: =F34 -> 0
A41: TỔNG NỘP VỀ | C41: =C36+C37+C38+C39-C40 -> 190000 | E41: Huỳnh Trọng Nhân

Sheet 06
A1: Ngày 07/08/2026 VINFAST TÂN HƯNG THU BÁN XE
A2: THU BÁN XE
A3: STT | B3: HỌ VÀ TÊN | C3: LOẠI XE | D3: POS | E3: GÓP | F3: TIỀN MẶT | G3: CHUYỂN KHOẢN | H3: CKCN | I3: NV BÁN | J3: GHI CHÚ
A4: 1 | B4: HOÀNG KHÁNH TRÂM | C4: EVO GRAND | E4: 22050000 | F4: 1000000
A5: 2 | B5: NGUYỄN QUỐC HOÀNG | C5: Flazz | G5: 14200000 | H5: 800000
A6: 3 | B6: NGUYỄN THỊ SÔNG HƯƠNG | C6: EVO GRAND LITE | G6: 14500000 | H6: 800000
F7: =SUM(F4:F6) -> 1000000 | G7: =SUM(G4:G6) -> 28700000 | H7: =SUM(H4:H6) -> 1600000 | I7: =F7+G7 -> 29700000
A8: THU BIỂN SỐ
A9: STT | B9: HỌ VÀ TÊN | C9: LOẠI XE | D9: CHUYỂN KHOẢN | E9: TIỀN MẶT | F9: NGƯỜI GIAO BIỂN SỐ | G9: NGƯỜI GIỮ BSỐ | I9: GHI CHÚ
A10: 1
E12: =SUM(E10:E11) -> 0 | W12: =6+3+6+2+3+5+16+14+4 -> 59
A13: CHI THUẾ + ĐĂNG KÝ BIỂN SỐ
A14: STT | B14: HỌ VÀ TÊN | C14: LOẠI XE | D14: THUẾ | E14: PHÍ BIỂN SỐ | F14: PHÍ CÔNG AN | G14: NGƯỜI NHÂN | I14: GHI CHÚ
A15: 1 | B15: HOÀNG KHÁNH TRÂM | C15: EVO GRAND | D15: 480000 | E15: 105000 | F15: 100000
A16: 2
A17: 3
A18: 4
D20: =SUM(D15:D19) -> 480000 | E20: =SUM(E15:E19) -> 105000 | F20: =SUM(F15:F19) -> 100000 | G20: =D20+E20+F20 -> 685000
A21: THU KHOẢN KHÁC
A22: STT | B22: NỘI DUNG | E22: SỐ TIỀN | F22: NGƯỜI THU | G22: CHT/KTT | I22: GHI CHÚ
B23: Thu quỹ giữ tiền mặt tại cửa hàng ngày 05/08/2026 | E23: 264000
E26: =SUM(E23:E25) -> 264000
A27: CHI PHÍ
A28: STT | B28: NỘI DUNG | E28: SỐ TIỀN CHI | F28: CKCN | G28: NGƯỜI CHI TIỀN | I28: NGƯỜI NHÂN TIỀN
B29: Chi quỹ giữ tiền mặt tại cửa hàng ngày 06/08/2026 | E29: =E23 -> 264000
B30: MIẾNG VÁ XE | E30: 160000
B31: KEO VÁ | E31: 175000
B32: BÚT XÓA | E32: 22000 | P32: TIỀN ỨNG
B33: ổ điện | E33: 160000 | P33: =G20+E30+E31+E32+E33+'04'!G20 -> 1747000
B34: nước | E34: 144000
E35: =SUM(E29:E34) -> 925000 | F35: =SUM(F29:F30) -> 0
C36: TM | D36: CK | G36: TIỀN MẶT | H36: CKCN | I36: CHUYỂN KHOẢN
A37: Bán Xe | C37: =F7 -> 1000000 | E37: DV NỘP VỀ | G37: =C39 -> 609000 | I37: =D39 -> 5300000
A38: Biển Số | C38: =E12 -> 0 | E38: BH NỘP VỀ | G38: =C42-C39 -> 315000 | H38: =H7+D12 -> 1600000 | I38: =G7 -> 28700000 | J38: =I38+H38 -> 30300000
A39: Dịch Vụ | C39: =1200000-661000+70000 -> 609000 | D39: 5300000
A40: Thu khác | C40: =E26 -> 264000 | E40: CỬA HÀNG TRƯỞNG
A41: Chi Phí | C41: =E35+G20-661000 -> 949000 | D41: =F35 -> 0
A42: TỔNG NỘP VỀ | C42: =C37+C39+C38+C40-C41 -> 924000 | E42: Huỳnh Trọng Nhân
N43: 4235000
J44: QUỸ | K44: 2564000
...

Sheet 07
A1: Ngày 07/08/2026 VINFAST TÂN HƯNG THU BÁN XE
A2: THU BÁN XE
A3: STT | B3: HỌ VÀ TÊN | C3: LOẠI XE | D3: POS | E3: GÓP | F3: TIỀN MẶT | G3: CHUYỂN KHOẢN | H3: CKCN | I3: NV BÁN | J3: GHI CHÚ
A4: 1 | B4: VÕ THÀNH NHÂN | C4: Feliz 2 | D4: 17790000 | H4: 1000000
A5: 2 | B5: TRẦN ĐẠI HƯNG | C5: EVO LITE | D5: 14300000 | H5: 800000
A6: 3 | B6: TRẦN ĐẠI HƯNG | C6: EVO LITE | D6: 14300000 | H6: 800000
A7: 4 | B7: TỐNG VĂN SONG | C7: EVO GRAND | E7: 22050000 | H7: 1000000
F8: =SUM(F4:F6) -> 0 | G8: =SUM(G4:G6) -> 0 | H8: =SUM(H4:H7) -> 3600000 | I8: =F8+G8 -> 0
A9: THU BIỂN SỐ
A10: STT | B10: HỌ VÀ TÊN | C10: LOẠI XE | D10: CHUYỂN KHOẢN | E10: TIỀN MẶT | F10: NGƯỜI GIAO BIỂN SỐ | G10: NGƯỜI GIỮ BSỐ | I10: GHI CHÚ
A11: 1 | B11: ĐẶNG NGỌC THANH TRÀ | E11: 1000000
E13: =SUM(E11:E12) -> 1000000 | W13: =6+3+6+2+3+5+16+14+4 -> 59
A14: CHI THUẾ + ĐĂNG KÝ BIỂN SỐ
A15: STT | B15: HỌ VÀ TÊN | C15: LOẠI XE | D15: THUẾ | E15: PHÍ BIỂN SỐ | F15: PHÍ CÔNG AN | G15: NGƯỜI NHÂN | I15: GHI CHÚ
A16: 1
A17: 2
A18: 3
A19: 4
D21: =SUM(D16:D20) -> 0 | E21: =SUM(E16:E20) -> 0 | F21: =SUM(F16:F20) -> 0 | G21: =D21+E21+F21 -> 0
A22: THU KHOẢN KHÁC
A23: STT | B23: NỘI DUNG | E23: SỐ TIỀN | F23: NGƯỜI THU | G23: CHT/KTT | H23: CKCN | I23: GHI CHÚ
B24: Thu quỹ giữ tiền mặt tại cửa hàng ngày 06/08/2026 | E24: 264000
B25: THU PHÍ CÀ THẺ TRẦN ĐẠI HƯNG (2 CHIẾC EVO LITE) | H25: 572000
B26: THU PHÍ CÀ THẺ VÕ THÀNH NHÂN | H26: 356000
E29: =SUM(E24:E26) -> 264000 | H29: =SUM(H25:H26) -> 928000
A30: CHI PHÍ
A31: STT | B31: NỘI DUNG | E31: SỐ TIỀN CHI | F31: CKCN | G31: NGƯỜI CHI TIỀN | I31: NGƯỜI NHÂN TIỀN
B32: Chi quỹ giữ tiền mặt tại cửa hàng ngày 07/08/2026 | E32: =E24+1000000 -> 1264000
P35: TIỀN ỨNG
P36: =G21+E33+E34+E35+E36+'04'!G20 -> 545000
E38: =SUM(E32:E37) -> 1264000 | F38: =SUM(F32:F33) -> 0
B39: TM | G39: TIỀN MẶT | H39: CKCN | I39: CHUYỂN KHOẢN
A40: Bán Xe | B40: =F8 -> 0 | E40: DV NỘP VỀ | G40: =C42 -> 2165000 | I40: =D42 | J40: =H8 -> 3600000
A41: Biển Số | C41: =E13 -> 1000000 | E41: BH NỘP VỀ | G41: =C45-C42 -> 0 | I41: =G8 -> 0 | J41: =I41+H41 -> 0
A42: Dịch Vụ | C42: =30000+120000+915000+120000+980000 -> 2165000
A43: Thu khác | C43: =E29 -> 264000 | E43: CỬA HÀNG TRƯỞNG
A44: Chi Phí | C44: =E38+G21 -> 1264000 | D44: =F38 -> 0
A45: TỔNG NỘP VỀ | C45: =C40+C42+C41+C43-C44 -> 2165000 | E45: Huỳnh Trọng Nhân
N46: 4235000
J47: QUỸ | K47: 2564000
...

Sheet 08
A1: Ngày 08/08/2026 VINFAST TÂN HƯNG THU BÁN XE
A2: THU BÁN XE
A3: STT | B3: HỌ VÀ TÊN | C3: LOẠI XE | D3: POS | E3: GÓP | F3: TIỀN MẶT | G3: CHUYỂN KHOẢN | H3: CKCN | I3: NV BÁN | J3: GHI CHÚ
A4: 1 | B4: ĐỖ CÔNG VƯỢNG | C4: EVO GRAND LITE | F4: 800000 | G4: 14500000
A5: 2 | B5: ĐỖ THANH NHƠN | C5: FELIZ 2 | D5: 17790000 | H5: 1000000
A6: 3 | B6: LÊ PHẠM HUỲNH BÁ KHUÊ | C6: EVO GRAND | G6: 22050000 | H6: 1000000
A7: 4
F8: =SUM(F4:F6) -> 800000 | G8: =SUM(G4:G6) -> 36550000 | H8: =SUM(H4:H7) -> 2000000 | I8: =F8+G8 -> 37350000
A9: THU BIỂN SỐ
A10: STT | B10: HỌ VÀ TÊN | C10: LOẠI XE | D10: CHUYỂN KHOẢN | E10: TIỀN MẶT | F10: NGƯỜI GIAO BIỂN SỐ | G10: NGƯỜI GIỮ BSỐ | I10: GHI CHÚ
A11: 1
E13: =SUM(E11:E12) -> 0 | W13: =6+3+6+2+3+5+16+14+4 -> 59
A14: CHI THUẾ + ĐĂNG KÝ BIỂN SỐ
A15: STT | B15: HỌ VÀ TÊN | C15: LOẠI XE | D15: THUẾ | E15: PHÍ BIỂN SỐ | F15: PHÍ CÔNG AN | G15: NGƯỜI NHÂN | I15: GHI CHÚ
A16: 1 | B16: ĐỖ CÔNG VƯỢNG | C16: EVO GRAND LITE | D16: 378000 | E16: 100000 | F16: 105000 | I16: PHƯƠNG
A17: 2
A18: 3
A19: 4
D21: =SUM(D16:D20) -> 378000 | E21: =SUM(E16:E20) -> 100000 | F21: =SUM(F16:F20) -> 105000 | G21: =D21+E21+F21 -> 583000
A22: THU KHOẢN KHÁC
A23: STT | B23: NỘI DUNG | E23: SỐ TIỀN | F23: NGƯỜI THU | G23: CHT/KTT | H23: CKCN | I23: GHI CHÚ
B24: Thu quỹ giữ tiền mặt tại cửa hàng ngày 07/08/2026 | E24: 1264000 | G24: PHƯƠNG
B25: thu phí cà thẻ ĐỖ THANH NHƠN | H25: 356000
E29: =SUM(E24:E26) -> 1264000 | H29: =SUM(H25:H26) -> 356000
A30: CHI PHÍ
A31: STT | B31: NỘI DUNG | E31: SỐ TIỀN CHI | F31: CKCN | G31: NGƯỜI CHI TIỀN | I31: NGƯỜI NHÂN TIỀN
B32: Chi quỹ giữ tiền mặt tại cửa hàng ngày 08/08/2026 | E32: =1264000-77000 -> 1187000 | G32: PHƯƠNG | H32: TMBH
B33: THÁO TIM VAN XE | E33: 20000 | G33: PHƯƠNG | H33: TMBH
B34: CHI TIỀN MUA LY | E34: 12000 | H34: TMBH
B35: CHI TIỀN MUA BAO RÁC | E35: 30000 | H35: TMBH | P35: TIỀN ỨNG
B36: CHI MUA BÌ TÀI LIỆU | E36: 15000 | H36: TMBH | P36: =G21+E33+E34+E35+E36+'04'!G20 -> 1205000
E38: =SUM(E32:E37) -> 1264000 | F38: =SUM(F32:F33) -> 0
C39: TM | D39: CK | G39: TIỀN MẶT | H39: CKCN | I39: CHUYỂN KHOẢN
A40: Bán Xe | C40: =F8 -> 800000 | E40: DV NỘP VỀ | G40: =C42 -> 1260000 | I40: =D42 -> 586630
A41: Biển Số | C41: =E13 -> 0 | E41: BH NỘP VỀ | G41: =C45-G40 -> 217000 | H41: =H8 -> 2000000 | I41: =G8 -> 36550000 | J41: =I41+H41 -> 38550000
A42: Dịch Vụ | C42: =750000+120000+120000+70000+200000 -> 1260000 | D42: 586630
A43: Thu khác | C43: =E29 -> 1264000 | E43: CỬA HÀNG TRƯỞNG
A44: Chi Phí | C44: =E38+G21 -> 1847000 | D44: =F38 -> 0
A45: TỔNG NỘP VỀ | C45: =C40+C42+C41+C43-C44 -> 1477000 | E45: Huỳnh Trọng Nhân
N46: 4235000
...
